Workbook

Sheet 设计基准
A1: 宝可梦怪物 · 攻击模式与数值设计基准
A2: 换算口径参照 Slay the Spire 2 的怪物实现（src/Core/Models/Monsters）与上表已有的生命值 / 防御 / 攻击三列。
A4: ① 攻击与防御 → 招式数值的换算系数
A5: 类别 | B5: 轻击系数 | C5: 中击系数 | D5: 重击系数 | E5: 格挡系数 | F5: 适用范围
A6: 普通 | B6: 0.16 | C6: 0.24 | D6: 0.34 | E6: 0.22 | F6: 种族值总和 ≤ 505（怪力）的怪物
A7: 精英 | B7: 0.2 | C7: 0.3 | D7: 0.4 | E7: 0.26 | F7: 种族值总和 > 505（怪力）的怪物，按精英数值设计
A9: ② 公式（总览表与招式表均以公式引用本页系数，改系数会连动全表）
A10: 轻击伤害 | B10: 攻击 × 轻击系数 | F10: 每回合都能打的小招
A11: 中击伤害 | B11: 攻击 × 中击系数 | F11: 主力输出招
A12: 重击伤害 | B12: 攻击 × 重击系数 | F12: 大招 / 爆发，通常放在循环末尾
A13: 多段伤害 | B13: 每段 = 中击 ÷ 段数，总伤害 ≈ 中击 | F13: 用于克制单次大格挡
A15: ③ STS2 原作数值参照（以下为源码中实际读到的数字，用于校准本表的档位）
A16: 分类 | B16: 生命区间 | C16: 单次攻击伤害 | D16: 多段攻击 | E16: 格挡 | F16: 强化（力量） | G16: 状态牌 | H16: 代表怪物
A17: 前期弱怪 | B17: 7 – 30 | C17: 3 – 9 | D17: 3 × 2 | E17: — | F17: +2 | G17: — | H17: CorpseSlug / Inklet / SneakyGremlin
A18: 普通怪 | B18: 30 – 70 | C18: 8 – 13 | D18: 8 × 2 | E18: 5 – 6 | F18: +2 | G18: 3 张 | H18: Nibbit / Chomper / GremlinMerc
A19: 高阶普通怪 | B19: 70 – 130 | C19: 15 – 19 | D19: 5 × 4 | E19: 6 | F19: +2 – +3 | G19: 3 张 | H19: SpinyToad / MagiKnight / Mawler
A20: 精英（前期） | B20: 100 – 170 | C20: 15 – 20 | D20: 7 – 10 × 2 – 3 | E20: 20 – 22 | F20: +2 – +3 | G20: 3 – 4 张 | H20: FlailKnight / TerrorEel / InfestedPrism / Entomancer
A21: 精英（后期） | B21: 230 – 320 | C21: 25 – 40 | D21: 6 × 4 | E21: 15 | F21: +3 – +5 | G21: 4 张 | H21: SoulNexus / MechaKnight
A22: Boss | B22: 220 – 420 | C22: 15 – 40 | D22: 3 – 5 × 5 | E22: 15 | F22: +2 – +4 | G22: 4 张 | H22: CeremonialBeast / Queen / WaterfallGiant
A23: 本表精英落点 | B23: 213 – 290 | C23: 26 – 52 | D23: 9 – 18 × 2 – 3 | E23: 21 – 32 | F23: +3 – +4 | G23: 2 – 3 张 | H23: 喷火龙 – 伊裴尔塔尔
A25: ④ 精英判定与设计约定
A26: 精英门槛 | B26: 种族值总和 > 505 | F26: 怪力的种族值总和为 505，它本身仍按普通怪处理
A27: 精英名单 | B27: 喷火龙 534 / 闪电鸟 580 / 巨金怪 600 / 基格尔德 600 / 凤王 680 / 哲尔尼亚斯 680 / 伊裤尔塔尔 680 | F27: 共 7 只
A28: 生命取值 | B28: 沿用名单表已有的「敌怪生命值」 | F28: 精英的强度通过招式倍率、多段、自身强化与穿透机制体现
A29: 数值对比 | B29: 怪力重击 33 → 喷火龙重击 38 → 伊裤尔塔尔重击 52 | F29: 精英重击明显高于怪力，符合「按精英数值设计」
A30: 固定伤害 / 穿透 | B30: 对付大岩蛇（格挡 22）、巨金怪（格挡 29）、凤王（格挡 32）的主要解法 | F30: 这三只的格挡高于同档怪物
A31: 沿用你的增益表 | B31: 涅槃（凤王）、壁垒（哲尔尼亚斯）、带电（闪电鸟） | F31: 直接挂你表里已有的增益名称

Sheet 怪物总览
A1: 怪物总览（共 37 只；轻击 / 中击 / 重击 / 格挡 为公式推导）
A3: Name | B3: 译名 | C3: 属性 | D3: 威胁等级 | E3: 类别 | F3: 定位 | G3: 生命值 | H3: 防御 | I3: 攻击 | J3: 随从生命值 | K3: 轻击 | L3: 中击 | M3: 重击 | N3: 格挡 | O3: 意图（行动循环） | P3: 特殊机制
A4: caterpie | B4: 绿毛虫 | C4: Bug | D4: 1 | E4: 普通 | F4: 干扰型 | G4: 160 | H4: 27 | I4: 25 | J4: 32 | K4: =ROUND(I4*IF($E4="精英",设计基准!$B$7,设计基准!$B$6),0) -> 4 | L4: =ROUND(I4*IF($E4="精英",设计基准!$C$7,设计基准!$C$6),0) -> 6 | M4: =ROUND(I4*IF($E4="精英",设计基准!$D$7,设计基准!$D$6),0) -> 9 | N4: =ROUND(H4*IF($E4="精英",设计基准!$E$7,设计基准!$E$6),0) -> 6 | O4: 削弱 → 轻击 → 防御 → 重击（循环）
A5: bounsweet | B5: 甜竹竹 | C5: Grass | D5: 1 | E5: 普通 | F5: 强化型 | G5: 155.2 | H5: 38 | I5: 30 | J5: 31 | K5: =ROUND(I5*IF($E5="精英",设计基准!$B$7,设计基准!$B$6),0) -> 5 | L5: =ROUND(I5*IF($E5="精英",设计基准!$C$7,设计基准!$C$6),0) -> 7 | M5: =ROUND(I5*IF($E5="精英",设计基准!$D$7,设计基准!$D$6),0) -> 10 | N5: =ROUND(H5*IF($E5="精英",设计基准!$E$7,设计基准!$E$6),0) -> 8 | O5: 强化 → 轻击 → 防御 （循环）
A6: bunnelby | B6: 掘掘兔 | C6: Normal | D6: 1 | E6: 普通 | F6: 干扰速攻 | G6: 148.8 | H6: 37 | I6: 34 | J6: 29 | K6: =ROUND(I6*IF($E6="精英",设计基准!$B$7,设计基准!$B$6),0) -> 5 | L6: =ROUND(I6*IF($E6="精英",设计基准!$C$7,设计基准!$C$6),0) -> 8 | M6: =ROUND(I6*IF($E6="精英",设计基准!$D$7,设计基准!$D$6),0) -> 12 | N6: =ROUND(H6*IF($E6="精英",设计基准!$E$7,设计基准!$E$6),0) -> 8 | O6: 削弱轻击 → 重击 → 防御 → 2段轻击（循环）
A7: mareep | B7: 咩利羊 | C7: Electric | D7: 1 | E7: 普通 | F7: 蓄力爆发 | G7: 176 | H7: 42 | I7: 52 | J7: 35 | K7: =ROUND(I7*IF($E7="精英",设计基准!$B$7,设计基准!$B$6),0) -> 8 | L7: =ROUND(I7*IF($E7="精英",设计基准!$C$7,设计基准!$C$6),0) -> 12 | M7: =ROUND(I7*IF($E7="精英",设计基准!$D$7,设计基准!$D$6),0) -> 18 | N7: =ROUND(H7*IF($E7="精英",设计基准!$E$7,设计基准!$E$6),0) -> 9 | O7: 强化 → 强化→ 防御 → 重击（循环）
A8: bellsprout | B8: 喇叭芽 | C8: Grass / Poison | D8: 2 | E8: 普通 | F8: 毒干扰 | G8: 168 | H8: 32 | I8: 72 | J8: 33 | K8: =ROUND(I8*IF($E8="精英",设计基准!$B$7,设计基准!$B$6),0) -> 12 | L8: =ROUND(I8*IF($E8="精英",设计基准!$C$7,设计基准!$C$6),0) -> 17 | M8: =ROUND(I8*IF($E8="精英",设计基准!$D$7,设计基准!$D$6),0) -> 24 | N8: =ROUND(H8*IF($E8="精英",设计基准!$E$7,设计基准!$E$6),0) -> 7 | O8: 第一回合施加中毒 ，然后改为 轻击 → 防御→ 中击（循环）
A9: geodude | B9: 小拳石 | C9: Rock / Ground | D9: 2 | E9: 普通 | F9: 坦克自爆 | G9: 152 | H9: 65 | I9: 55 | J9: 30 | K9: =ROUND(I9*IF($E9="精英",设计基准!$B$7,设计基准!$B$6),0) -> 9 | L9: =ROUND(I9*IF($E9="精英",设计基准!$C$7,设计基准!$C$6),0) -> 13 | M9: =ROUND(I9*IF($E9="精英",设计基准!$D$7,设计基准!$D$6),0) -> 19 | N9: =ROUND(H9*IF($E9="精英",设计基准!$E$7,设计基准!$E$6),0) -> 14 | O9: 防御 → 中击循环；残血改为自爆
A10: goomy | B10: 黏黏宝 | C10: Dragon | D10: 2 | E10: 普通 | F10: 吸血坦克 | G10: 160 | H10: 55 | I10: 52 | J10: 32 | K10: =ROUND(I10*IF($E10="精英",设计基准!$B$7,设计基准!$B$6),0) -> 8 | L10: =ROUND(I10*IF($E10="精英",设计基准!$C$7,设计基准!$C$6),0) -> 12 | M10: =ROUND(I10*IF($E10="精英",设计基准!$D$7,设计基准!$D$6),0) -> 18 | N10: =ROUND(H10*IF($E10="精英",设计基准!$E$7,设计基准!$E$6),0) -> 12 | O10: 削弱 → 轻击 → 吸血 → 防御（循环）
A11: corphish | B11: 龙虾小兵 | C11: Water | D11: 2 | E11: 普通 | F11: 硬壳输出 | G11: 156.8 | H11: 50 | I11: 65 | J11: 31 | K11: =ROUND(I11*IF($E11="精英",设计基准!$B$7,设计基准!$B$6),0) -> 10 | L11: =ROUND(I11*IF($E11="精英",设计基准!$C$7,设计基准!$C$6),0) -> 16 | M11: =ROUND(I11*IF($E11="精英",设计基准!$D$7,设计基准!$D$6),0) -> 22 | N11: =ROUND(H11*IF($E11="精英",设计基准!$E$7,设计基准!$E$6),0) -> 11 | O11: 轻击 → 防御强化 → 轻击 → 重击（循环）
A12: charmander | B12: 小火龙 | C12: Fire | D12: 2 | E12: 普通 | F12: 灼烧输出 | G12: 150.4 | H12: 46 | I12: 56 | J12: 30 | K12: =ROUND(I12*IF($E12="精英",设计基准!$B$7,设计基准!$B$6),0) -> 9 | L12: =ROUND(I12*IF($E12="精英",设计基准!$C$7,设计基准!$C$6),0) -> 13 | M12: =ROUND(I12*IF($E12="精英",设计基准!$D$7,设计基准!$D$6),0) -> 19 | N12: =ROUND(H12*IF($E12="精英",设计基准!$E$7,设计基准!$E$6),0) -> 10 | O12: 削弱 → 轻击 → 塞灼烧 → 重击（循环）
A13: slowpoke | B13: 呆呆兽 | C13: Water / Psychic | D13: 2 | E13: 普通 | F13: 超耐久消耗 | G13: 232 | H13: 52 | I13: 52 | J13: 46 | K13: =ROUND(I13*IF($E13="精英",设计基准!$B$7,设计基准!$B$6),0) -> 8 | L13: =ROUND(I13*IF($E13="精英",设计基准!$C$7,设计基准!$C$6),0) -> 12 | M13: =ROUND(I13*IF($E13="精英",设计基准!$D$7,设计基准!$D$6),0) -> 18 | N13: =ROUND(H13*IF($E13="精英",设计基准!$E$7,设计基准!$E$6),0) -> 11 | O13: 轻击 → 削弱 → 治疗防御 → 轻击（循环）
A14: bulbasaur | B14: 妙蛙种子 | C14: Grass / Poison | D14: 2 | E14: 普通 | F14: 均衡消耗 | G14: 160 | H14: 57 | I14: 57 | J14: 32 | K14: =ROUND(I14*IF($E14="精英",设计基准!$B$7,设计基准!$B$6),0) -> 9 | L14: =ROUND(I14*IF($E14="精英",设计基准!$C$7,设计基准!$C$6),0) -> 14 | M14: =ROUND(I14*IF($E14="精英",设计基准!$D$7,设计基准!$D$6),0) -> 19 | N14: =ROUND(H14*IF($E14="精英",设计基准!$E$7,设计基准!$E$6),0) -> 13 | O14: 中毒 → 轻击 → 防御 → 轻击（循环）
A15: chikorita | B15: 菊草叶 | C15: Grass | D15: 2 | E15: 普通 | F15: 纯防御 | G15: 160 | H15: 65 | I15: 49 | J15: 32 | K15: =ROUND(I15*IF($E15="精英",设计基准!$B$7,设计基准!$B$6),0) -> 8 | L15: =ROUND(I15*IF($E15="精英",设计基准!$C$7,设计基准!$C$6),0) -> 12 | M15: =ROUND(I15*IF($E15="精英",设计基准!$D$7,设计基准!$D$6),0) -> 17 | N15: =ROUND(H15*IF($E15="精英",设计基准!$E$7,设计基准!$E$6),0) -> 14 | O15: 防御 → 轻击 → 强化 （循环）
... A17: exeggcute | B17: 蛋蛋 | C17: Grass / Psychic | D17: 2 | E17: 普通 | F17: 干扰控制 | G17: 184 | H17: 62 | I17: 50 | J17: 36 | K17: =ROUND(I17*IF($E17="精英",设计基准!$B$7,设计基准!$B$6),0) -> 8 | L17: =ROUND(I17*IF($E17="精英",设计基准!$C$7,设计基准!$C$6),0) -> 12 | M17: =ROUND(I17*IF($E17="精英",设计基准!$D$7,设计基准!$D$6),0) -> 17 | N17: =ROUND(H17*IF($E17="精英",设计基准!$E$7,设计基准!$E$6),0) -> 14 | O17: 轻击塞牌 → 轻击 → 防御 → 削弱（循环）
A18: farfetchd | B18: 大葱鸭 | C18: Normal / Flying | D18: 2 | E18: 普通 | F18: 高攻强化 | G18: 171.2 | H18: 58 | I18: 74 | J18: 34 | K18: 3 | L18: =ROUND(I18*IF($E18="精英",设计基准!$C$7,设计基准!$C$6),0) -> 18 | M18: =ROUND(I18*IF($E18="精英",设计基准!$D$7,设计基准!$D$6),0) -> 25 | N18: =ROUND(H18*IF($E18="精英",设计基准!$E$7,设计基准!$E$6),0) -> 13 | O18: 第一回合强化，然后 4段轻击 → 重击（循环）
A19: lickitung | B19: 大舌头 | C19: Normal | D19: 2 | E19: 普通 | F19: 控制坦克 | G19: 232 | H19: 75 | I19: 57 | J19: 46 | K19: =ROUND(I19*IF($E19="精英",设计基准!$B$7,设计基准!$B$6),0) -> 9 | L19: =ROUND(I19*IF($E19="精英",设计基准!$C$7,设计基准!$C$6),0) -> 14 | M19: =ROUND(I19*IF($E19="精英",设计基准!$D$7,设计基准!$D$6),0) -> 19 | N19: =ROUND(H19*IF($E19="精英",设计基准!$E$7,设计基准!$E$6),0) -> 17 | O19: 削弱轻击 → 防御 → 削弱 → 轻击（循环）
A20: onix | B20: 大岩蛇 | C20: Rock / Ground | D20: 2 | E20: 普通 | F20: 极限防御 | G20: 144 | H20: 102 | I20: 37 | J20: 28 | K20: =ROUND(I20*IF($E20="精英",设计基准!$B$7,设计基准!$B$6),0) -> 6 | L20: =ROUND(I20*IF($E20="精英",设计基准!$C$7,设计基准!$C$6),0) -> 9 | M20: =ROUND(I20*IF($E20="精英",设计基准!$D$7,设计基准!$D$6),0) -> 13 | N20: =ROUND(H20*IF($E20="精英",设计基准!$E$7,设计基准!$E$6),0) -> 22 | O20: 防御 → 轻击 → 轻击 → 轻击（循环）
A21: butterfree | B21: 巴大蝶 | C21: Bug / Flying | D21: 2 | E21: 普通 | F21: 状态干扰 | G21: 184 | H21: 65 | I21: 67 | J21: 36 | K21: =ROUND(I21*IF($E21="精英",设计基准!$B$7,设计基准!$B$6),0) -> 11 | L21: =ROUND(I21*IF($E21="精英",设计基准!$C$7,设计基准!$C$6),0) -> 16 | M21: =ROUND(I21*IF($E21="精英",设计基准!$D$7,设计基准!$D$6),0) -> 23 | N21: =ROUND(H21*IF($E21="精英",设计基准!$E$7,设计基准!$E$6),0) -> 14 | O21: 塞状态牌 → 轻击 → 削弱 → 轻击（循环）
A22: parasect | B22: 派拉斯特 | C22: Bug / Grass | D22: 2 | E22: 普通 | F22: 吸血输出 | G22: 184 | H22: 80 | I22: 77 | J22: 36 | K22: =ROUND(I22*IF($E22="精英",设计基准!$B$7,设计基准!$B$6),0) -> 12 | L22: =ROUND(I22*IF($E22="精英",设计基准!$C$7,设计基准!$C$6),0) -> 18 | M22: =ROUND(I22*IF($E22="精英",设计基准!$D$7,设计基准!$D$6),0) -> 26 | N22: =ROUND(H22*IF($E22="精英",设计基准!$E$7,设计基准!$E$6),0) -> 18 | O22: 削弱 → 多段轻击 → 吸血 → 重击（循环）
A23: dugtrio | B23: 三地鼠 | C23: Ground | D23: 3 | E23: 普通 | F23: 速攻爆发 | G23: 144 | H23: 60 | I23: 75 | J23: 28 | K23: =ROUND(I23*IF($E23="精英",设计基准!$B$7,设计基准!$B$6),0) -> 12 | L23: =ROUND(I23*IF($E23="精英",设计基准!$C$7,设计基准!$C$6),0) -> 18 | M23: =ROUND(I23*IF($E23="精英",设计基准!$D$7,设计基准!$D$6),0) -> 26 | N23: =ROUND(H23*IF($E23="精英",设计基准!$E$7,设计基准!$E$6),0) -> 13 | O23: 削弱 → 多段轻击 → 轻击 → 重击（循环）
A24: miltank | B24: 大奶罐 | C24: Normal | D24: 3 | E24: 普通 | F24: 治疗坦克 | G24: 240 | H24: 87 | I24: 60 | J24: 48 | K24: =ROUND(I24*IF($E24="精英",设计基准!$B$7,设计基准!$B$6),0) -> 10 | L24: =ROUND(I24*IF($E24="精英",设计基准!$C$7,设计基准!$C$6),0) -> 14 | M24: =ROUND(I24*IF($E24="精英",设计基准!$D$7,设计基准!$D$6),0) -> 20 | N24: =ROUND(H24*IF($E24="精英",设计基准!$E$7,设计基准!$E$6),0) -> 19 | O24: 治疗 → 轻击 → 轻击 → 净化防御（循环）
A25: gengar | B25: 耿鬼 | C25: Ghost / Poison | D25: 3 | E25: 普通 | F25: 高攻脆皮 | G25: 184 | H25: 67 | I25: 97 | J25: 36 | K25: =ROUND(I25*IF($E25="精英",设计基准!$B$7,设计基准!$B$6),0) -> 16 | L25: =ROUND(I25*IF($E25="精英",设计基准!$C$7,设计基准!$C$6),0) -> 23 | M25: =ROUND(I25*IF($E25="精英",设计基准!$D$7,设计基准!$D$6),0) -> 33 | N25: =ROUND(H25*IF($E25="精英",设计基准!$E$7,设计基准!$E$6),0) -> 15 | O25: 塞状态牌 → 削弱 → 轻击 （循环）
A26: heracross | B26: 赫拉克罗斯 | C26: Bug / Fighting | D26: 3 | E26: 普通 | F26: 成长输出 | G26: 216 | H26: 85 | I26: 82 | J26: 43 | K26: =ROUND(I26*IF($E26="精英",设计基准!$B$7,设计基准!$B$6),0) -> 13 | L26: =ROUND(I26*IF($E26="精英",设计基准!$C$7,设计基准!$C$6),0) -> 20 | M26: =ROUND(I26*IF($E26="精英",设计基准!$D$7,设计基准!$D$6),0) -> 28 | N26: =ROUND(H26*IF($E26="精英",设计基准!$E$7,设计基准!$E$6),0) -> 19 | O26: 强化 → 轻击 → 重击（循环）
A27: machamp | B27: 怪力 | C27: Fighting | D27: 3 | E27: 普通 | F27: 基准·成长爆发 | G27: 232 | H27: 82 | I27: 97 | J27: 46 | K27: =ROUND(I27*IF($E27="精英",设计基准!$B$7,设计基准!$B$6),0) -> 16 | L27: =ROUND(I27*IF($E27="精英",设计基准!$C$7,设计基准!$C$6),0) -> 23 | M27: =ROUND(I27*IF($E27="精英",设计基准!$D$7,设计基准!$D$6),0) -> 33 | N27: =ROUND(H27*IF($E27="精英",设计基准!$E$7,设计基准!$E$6),0) -> 18 | O27: 强化 → 2段轻击 （循环）
A28: charizard | B28: 喷火龙 | C28: Fire / Flying | D28: 3 | E28: 精英 | F28: 精英·灼烧成长 | G28: 212.8 | H28: 81 | I28: 96 | J28: 42 | K28: =ROUND(I28*IF($E28="精英",设计基准!$B$7,设计基准!$B$6),0) -> 19 | L28: =ROUND(I28*IF($E28="精英",设计基准!$C$7,设计基准!$C$6),0) -> 29 | M28: =ROUND(I28*IF($E28="精英",设计基准!$D$7,设计基准!$D$6),0) -> 38 | N28: =ROUND(H28*IF($E28="精英",设计基准!$E$7,设计基准!$E$6),0) -> 21 | O28: 防御强化 → 轻击 → 塞灼烧 → 重击；半血后转全攻 | P28: 生命 ≤ 50% 后不再使用龙之舞，改为翅膀攻击 → 火焰旋涡 → 大字爆炎 进入狂暴
A29: zapdos | B29: 闪电鸟 | C29: Electric / Flying | D29: 4 | E29: 精英 | F29: 精英·塞牌压制 | G29: 232 | H29: 87 | I29: 107 | J29: 46 | K29: =ROUND(I29*IF($E29="精英",设计基准!$B$7,设计基准!$B$6),0) -> 21 | L29: =ROUND(I29*IF($E29="精英",设计基准!$C$7,设计基准!$C$6),0) -> 32 | M29: =ROUND(I29*IF($E29="精英",设计基准!$D$7,设计基准!$D$6),0) -> 43 | N29: =ROUND(H29*IF($E29="精英",设计基准!$E$7,设计基准!$E$6),0) -> 23 | O29: 防御强化 → 轻击 → 轻击 → 塞「带电」重击（循环） | P29: 打雷往玩家牌堆塞入「带电」（出牌时对随机敌人造成 8 伤害）—— 出牌越多越痛
A30: metagross | B30: 巨金怪 | C30: Steel / Psychic | D30: 4 | E30: 精英 | F30: 精英·铁壁重击 | G30: 216 | H30: 110 | I30: 115 | J30: 43 | K30: =ROUND(I30*IF($E30="精英",设计基准!$B$7,设计基准!$B$6),0) -> 23 | L30: =ROUND(I30*IF($E30="精英",设计基准!$C$7,设计基准!$C$6),0) -> 35 | M30: =ROUND(I30*IF($E30="精英",设计基准!$D$7,设计基准!$D$6),0) -> 46 | N30: =ROUND(H30*IF($E30="精英",设计基准!$E$7,设计基准!$E$6),0) -> 29 | O30: 防御强化 → 2段轻击 → 重击 （循环） | P30: 攻击 115、防御 110 均为全表最高档；格挡 29 + 3 段攻击 —— 需要固定伤害或穿透
A31: zygarde-50 | B31: 基格尔德 | C31: Dragon / Ground | D31: 4 | E31: 精英 | F31: 精英·多段压制 | G31: 260.8 | H31: 108 | I31: 90 | J31: 52 | K31: =ROUND(I31*IF($E31="精英",设计基准!$B$7,设计基准!$B$6),0) -> 18 | L31: =ROUND(I31*IF($E31="精英",设计基准!$C$7,设计基准!$C$6),0) -> 27 | M31: =ROUND(I31*IF($E31="精英",设计基准!$D$7,设计基准!$D$6),0) -> 36 | N31: =ROUND(H31*IF($E31="精英",设计基准!$E$7,设计基准!$E$6),0) -> 28 | O31: 防御强化 → 1段轻击 → 重击（循环） | P31: 生命 261 + 3 段攻击，对格挡流克制，需要减伤或避闪
A32: ho-oh | B32: 凤王 | C32: Fire / Flying | D32: 4 | E32: 精英 | F32: 精英·复活爆发 | G32: 257.6 | H32: 122 | I32: 120 | J32: 51 | K32: =ROUND(I32*IF($E32="精英",设计基准!$B$7,设计基准!$B$6),0) -> 24 | L32: =ROUND(I32*IF($E32="精英",设计基准!$C$7,设计基准!$C$6),0) -> 36 | M32: =ROUND(I32*IF($E32="精英",设计基准!$D$7,设计基准!$D$6),0) -> 48 | N32: =ROUND(H32*IF($E32="精英",设计基准!$E$7,设计基准!$E$6),0) -> 32 | O32: 防御强化 → 轻击 → 塞灼烧 → 重击；死亡后召唤凤凰蛋
A33: xerneas | B33: 哲尔尼亚斯 | C33: Fairy | D33: 4 | E33: 精英 | F33: 精英·壁垒续航 | G33: 289.6 | H33: 96 | I33: 131 | J33: 57 | K33: =ROUND(I33*IF($E33="精英",设计基准!$B$7,设计基准!$B$6),0) -> 26 | L33: =ROUND(I33*IF($E33="精英",设计基准!$C$7,设计基准!$C$6),0) -> 39 | M33: =ROUND(I33*IF($E33="精英",设计基准!$D$7,设计基准!$D$6),0) -> 52 | N33: =ROUND(H33*IF($E33="精英",设计基准!$E$7,设计基准!$E$6),0) -> 25 | O33: 防御强化 → 轻击 → 吸血 → 重击；格挡回合结束不消失 | P33: 「壁垒」=回合结束时格挡不消失（对应增益表），配合木角吸血构成超长线消耗战
A34: yveltal | B34: 伊裴尔塔尔 | C34: Dark / Flying | D34: 4 | E34: 精英 | F34: 精英·吸血压制 | G34: 289.6 | H34: 96 | I34: 131 | J34: 57 | K34: =ROUND(I34*IF($E34="精英",设计基准!$B$7,设计基准!$B$6),0) -> 26 | L34: =ROUND(I34*IF($E34="精英",设计基准!$C$7,设计基准!$C$6),0) -> 39 | M34: =ROUND(I34*IF($E34="精英",设计基准!$D$7,设计基准!$D$6),0) -> 52 | N34: =ROUND(H34*IF($E34="精英",设计基准!$E$7,设计基准!$E$6),0) -> 25 | O34: 强化 → 削弱轻击 → 吸血 → 塞牌重击；半血后每回合额外施加虚弱 | P34: 生命 ≤ 50% 后每回合开始给玩家 1 层虚弱；与哲尔尼亚斯对称 —— 一个续航、一个压制
A35: ho-oh's egg | B35: 凤凰蛋 | C35: Fire / Flying | D35: 4 | E35: 特殊 | F35: 特殊·倒计时召唤 | G35: 1 | H35: 0 | I35: 0 | J35: 1 | K35: =ROUND(I35*IF($E35="精英",设计基准!$B$7,设计基准!$B$6),0) -> 0 | L35: =ROUND(I35*IF($E35="精英",设计基准!$C$7,设计基准!$C$6),0) -> 0 | M35: =ROUND(I35*IF($E35="精英",设计基准!$D$7,设计基准!$D$6),0) -> 0 | N35: =ROUND(H35*IF($E35="精英",设计基准!$E$7,设计基准!$E$6),0) -> 0 | O35: 待机 2 回合 → 召唤凤王 | P35: 生命 1；只要场上还有其它敌人就无法被选为目标 —— 本质是 2 回合倒计时
A37: 设计自检
A38: 精英重击最低值 | C38: =_xlfn.MINIFS(M4:M35,E4:E35,"精英") -> 36
A39: 普通重击最高值 | C39: =_xlfn.MAXIFS(M4:M35,E4:E35,"普通") -> 33
A40: 精英重击高出普通 | C40: =IF(C38>C39,"✅ 精英重击高于全部普通怪","‼ 不通过") -> ✅ 精英重击高于全部普通怪
A41: 招式检查异常数 | C41: =COUNTIF(招式表!$L$4:$L$181,"‼")+COUNTIF(招式表!$G$4:$G$181,"<1") -> 0
A42: 招式总数 | C42: =COUNTA(招式表!$C$4:$C$181) -> 127

Sheet 招式表
A1: 招式表（一行一个招式；「伤害」与「总伤害」为公式，引自怪物总览）
A3: 译名 | B3: 类别 | C3: 招式 | D3: 意图类型 | E3: 数值档位 | F3: 伤害（每段） | G3: 段数 | H3: 总伤害 | I3: 获得格挡 | J3: 附加效果 | K3: 备注 | L3: 检查
A4: 绿毛虫 | B4: 普通 | C4: 吐丝 | D4: 削弱 | E4: 无 | F4: =0 -> 0 | G4: 1 | H4: =F4*G4 -> 0 | I4: 0 | J4: 玩家获得 1 层虚弱 | L4: =IF(OR(G4<1,I4<0),"\u203c","OK") -> OK
A5: 绿毛虫 | B5: 普通 | C5: 虫咬 | D5: 攻击 | E5: 轻击 | F5: =怪物总览!K4 -> 4 | G5: 1 | H5: =F5*G5 -> 4 | I5: 0 | J5: — | L5: =IF(OR(G5<1,I5<0),"\u203c","OK") -> OK
A6: 绿毛虫 | B6: 普通 | C6: 蜷缩 | D6: 防御 | E6: 无 | F6: =0 -> 0 | G6: 1 | H6: =F6*G6 -> 0 | I6: =怪物总览!N4 -> 6 | J6: — | L6: =IF(OR(G6<1,I6<0),"\u203c","OK") -> OK
A7: 绿毛虫 | B7: 普通 | C7: 撞击 | D7: 攻击 | E7: 中击 | F7: =怪物总览!L4 -> 6 | G7: 1 | H7: =F7*G7 -> 6 | I7: 0 | J7: — | L7: =IF(OR(G7<1,I7<0),"\u203c","OK") -> OK
A8: 甜竹竹 | B8: 普通 | C8: 香甜气息 | D8: 强化 | E8: 无 | F8: =0 -> 0 | G8: 1 | H8: =F8*G8 -> 0 | I8: 0 | J8: 自身 +2 力量 | L8: =IF(OR(G8<1,I8<0),"\u203c","OK") -> OK
A9: 甜竹竹 | B9: 普通 | C9: 撞击 | D9: 攻击 | E9: 轻击 | F9: =怪物总览!K5 -> 5 | G9: 1 | H9: =F9*G9 -> 5 | I9: 0 | J9: — | L9: =IF(OR(G9<1,I9<0),"\u203c","OK") -> OK
A10: 甜竹竹 | B10: 普通 | C10: 光合作用 | D10: 防御 | E10: 无 | F10: =0 -> 0 | G10: 1 | H10: =F10*G10 -> 0 | I10: =怪物总览!N5 -> 8 | J10: — | L10: =IF(OR(G10<1,I10<0),"\u203c","OK") -> OK
A11: 甜竹竹 | B11: 普通 | C11: 飞叶快刀 | D11: 攻击 | E11: 中击 | F11: =怪物总览!L5 -> 7 | G11: 1 | H11: =F11*G11 -> 7 | I11: 0 | J11: — | L11: =IF(OR(G11<1,I11<0),"\u203c","OK") -> OK
A12: 掘掘兔 | B12: 普通 | C12: 泥巴射击 | D12: 削弱+攻击 | E12: 轻击 | F12: =怪物总览!K6 -> 5 | G12: 1 | H12: =F12*G12 -> 5 | I12: 0 | J12: 玩家获得 1 层虚弱 | L12: =IF(OR(G12<1,I12<0),"\u203c","OK") -> OK
A13: 掘掘兔 | B13: 普通 | C13: 挖洞 | D13: 攻击 | E13: 中击 | F13: =怪物总览!L6 -> 8 | G13: 1 | H13: =F13*G13 -> 8 | I13: 0 | J13: — | L13: =IF(OR(G13<1,I13<0),"\u203c","OK") -> OK
A14: 掘掘兔 | B14: 普通 | C14: 掘地 | D14: 防御 | E14: 无 | F14: =0 -> 0 | G14: 1 | H14: =F14*G14 -> 0 | I14: =怪物总览!N6 -> 8 | J14: — | L14: =IF(OR(G14<1,I14<0),"\u203c","OK") -> OK
A15: 掘掘兔 | B15: 普通 | C15: 二连踢 | D15: 多段攻击 | E15: 多段 | F15: =ROUND(怪物总览!L6/G15,0) -> 4 | G15: 2 | H15: =F15*G15 -> 8 | I15: 0 | J15: — | L15: =IF(OR(G15<1,I15<0),"\u203c","OK") -> OK
A16: 咩利羊 | B16: 普通 | C16: 静电 | D16: 强化 | E16: 无 | F16: =0 -> 0 | G16: 1 | H16: =F16*G16 -> 0 | I16: 0 | J16: 自身 +2 力量 | L16: =IF(OR(G16<1,I16<0),"\u203c","OK") -> OK
A17: 咩利羊 | B17: 普通 | C17: 电击 | D17: 攻击 | E17: 轻击 | F17: =怪物总览!K7 -> 8 | G17: 1 | H17: =F17*G17 -> 8 | I17: 0 | J17: — | L17: =IF(OR(G17<1,I17<0),"\u203c","OK") -> OK
A18: 咩利羊 | B18: 普通 | C18: 充电 | D18: 防御 | E18: 无 | F18: =0 -> 0 | G18: 1 | H18: =F18*G18 -> 0 | I18: =怪物总览!N7 -> 9 | J18: — | K18: 充电后下一击会带着强化落下 | L18: =IF(OR(G18<1,I18<0),"\u203c","OK") -> OK
A19: 咩利羊 | B19: 普通 | C19: 电磁炮 | D19: 攻击 | E19: 重击 | F19: =怪物总览!M7 -> 18 | G19: 1 | H19: =F19*G19 -> 18 | I19: 0 | J19: — | L19: =IF(OR(G19<1,I19<0),"\u203c","OK") -> OK
A20: 宝贝龙 | B20: 普通 | C20: 咬住 | D20: 攻击 | E20: 轻击 | F20: =怪物总览!#REF! -> #REF! | G20: 1 | H20: =F20*G20 -> #REF! | I20: 0 | J20: — | L20: =IF(OR(G20<1,I20<0),"\u203c","OK") -> OK
A21: 喇叭芽 | B21: 普通 | C21: 毒粉 | D21: 削弱 | E21: 无 | F21: =0 -> 0 | G21: 1 | H21: =F21*G21 -> 0 | I21: 0 | J21: 玩家获得 2 层中毒 | L21: =IF(OR(G21<1,I21<0),"\u203c","OK") -> OK
A22: 喇叭芽 | B22: 普通 | C22: 藤鞄 | D22: 攻击 | E22: 轻击 | F22: =怪物总览!K8 -> 12 | G22: 1 | H22: =F22*G22 -> 12 | I22: 0 | J22: — | L22: =IF(OR(G22<1,I22<0),"\u203c","OK") -> OK
A23: 喇叭芽 | B23: 普通 | C23: 生长 | D23: 强化 | E23: 无 | F23: =0 -> 0 | G23: 1 | H23: =F23*G23 -> 0 | I23: 0 | J23: 自身 +2 力量 | L23: =IF(OR(G23<1,I23<0),"\u203c","OK") -> OK
A24: 喇叭芽 | B24: 普通 | C24: 咬住 | D24: 攻击 | E24: 中击 | F24: =怪物总览!L8 -> 17 | G24: 1 | H24: =F24*G24 -> 17 | I24: 0 | J24: — | L24: =IF(OR(G24<1,I24<0),"\u203c","OK") -> OK
A25: 小拳石 | B25: 普通 | C25: 变硬 | D25: 防御 | E25: 无 | F25: =0 -> 0 | G25: 1 | H25: =F25*G25 -> 0 | I25: =怪物总览!N9 -> 14 | J25: — | L25: =IF(OR(G25<1,I25<0),"\u203c","OK") -> OK
A26: 小拳石 | B26: 普通 | C26: 撞击 | D26: 攻击 | E26: 轻击 | F26: =怪物总览!K9 -> 9 | G26: 1 | H26: =F26*G26 -> 9 | I26: 0 | J26: — | L26: =IF(OR(G26<1,I26<0),"\u203c","OK") -> OK
A27: 小拳石 | B27: 普通 | C27: 岩石封锁 | D27: 攻击+削弱 | E27: 中击 | F27: =怪物总览!L9 -> 13 | G27: 1 | H27: =F27*G27 -> 13 | I27: 0 | J27: 玩家获得 1 层破绽 | L27: =IF(OR(G27<1,I27<0),"\u203c","OK") -> OK
A28: 小拳石 | B28: 普通 | C28: 自爆 | D28: 攻击 | E28: 重击 | F28: =怪物总览!M9 -> 19 | G28: 1 | H28: =F28*G28 -> 19 | I28: 0 | J28: 自身失去 10 点生命 | K28: 仅在生命 ≤ 30% 时使用 | L28: =IF(OR(G28<1,I28<0),"\u203c","OK") -> OK
A29: 黏黏宝 | B29: 普通 | C29: 黏液 | D29: 削弱 | E29: 无 | F29: =0 -> 0 | G29: 1 | H29: =F29*G29 -> 0 | I29: 0 | J29: 玩家获得 2 层虚弱 | L29: =IF(OR(G29<1,I29<0),"\u203c","OK") -> OK
A30: 黏黏宝 | B30: 普通 | C30: 撞击 | D30: 攻击 | E30: 轻击 | F30: =怪物总览!K10 -> 8 | G30: 1 | H30: =F30*G30 -> 8 | I30: 0 | J30: — | L30: =IF(OR(G30<1,I30<0),"\u203c","OK") -> OK
A31: 黏黏宝 | B31: 普通 | C31: 吸收 | D31: 攻击+吸血 | E31: 中击 | F31: =怪物总览!L10 -> 12 | G31: 1 | H31: =F31*G31 -> 12 | I31: 0 | J31: 自身回复 6 点生命 | L31: =IF(OR(G31<1,I31<0),"\u203c","OK") -> OK
A32: 黏黏宝 | B32: 普通 | C32: 硬化 | D32: 防御 | E32: 无 | F32: =0 -> 0 | G32: 1 | H32: =F32*G32 -> 0 | I32: =怪物总览!N10 -> 12 | J32: — | L32: =IF(OR(G32<1,I32<0),"\u203c","OK") -> OK
A33: 龙虾小兵 | B33: 普通 | C33: 泡沫 | D33: 攻击 | E33: 轻击 | F33: =怪物总览!K11 -> 10 | G33: 1 | H33: =F33*G33 -> 10 | I33: 0 | J33: — | L33: =IF(OR(G33<1,I33<0),"\u203c","OK") -> OK
A34: 龙虾小兵 | B34: 普通 | C34: 硬壳 | D34: 防御+强化 | E34: 无 | F34: =0 -> 0 | G34: 1 | H34: =F34*G34 -> 0 | I34: =怪物总览!N11 -> 11 | J34: 自身 +2 力量 | L34: =IF(OR(G34<1,I34<0),"\u203c","OK") -> OK
A35: 龙虾小兵 | B35: 普通 | C35: 蟹钳锤 | D35: 攻击 | E35: 中击 | F35: =怪物总览!L11 -> 16 | G35: 1 | H35: =F35*G35 -> 16 | I35: 0 | J35: — | L35: =IF(OR(G35<1,I35<0),"\u203c","OK") -> OK
A36: 龙虾小兵 | B36: 普通 | C36: 贝壳刃 | D36: 攻击 | E36: 重击 | F36: =怪物总览!M11 -> 22 | G36: 1 | H36: =F36*G36 -> 22 | I36: 0 | J36: — | L36: =IF(OR(G36<1,I36<0),"\u203c","OK") -> OK
A37: 小火龙 | B37: 普通 | C37: 摇尾巴 | D37: 削弱 | E37: 无 | F37: =0 -> 0 | G37: 1 | H37: =F37*G37 -> 0 | I37: 0 | J37: 玩家获得 1 层破绽 | L37: =IF(OR(G37<1,I37<0),"\u203c","OK") -> OK
A38: 小火龙 | B38: 普通 | C38: 抓 | D38: 攻击 | E38: 轻击 | F38: =怪物总览!K12 -> 9 | G38: 1 | H38: =F38*G38 -> 9 | I38: 0 | J38: — | L38: =IF(OR(G38<1,I38<0),"\u203c","OK") -> OK
A39: 小火龙 | B39: 普通 | C39: 火花 | D39: 攻击+塞牌 | E39: 中击 | F39: =怪物总览!L12 -> 13 | G39: 1 | H39: =F39*G39 -> 13 | I39: 0 | J39: 玩家弃牌堆塞入 1 张「灼烧」 | L39: =IF(OR(G39<1,I39<0),"\u203c","OK") -> OK
A40: 小火龙 | B40: 普通 | C40: 火焰牙 | D40: 攻击 | E40: 重击 | F40: =怪物总览!M12 -> 19 | G40: 1 | H40: =F40*G40 -> 19 | I40: 0 | J40: — | L40: =IF(OR(G40<1,I40<0),"\u203c","OK") -> OK
A41: 呆呆兽 | B41: 普通 | C41: 撞击 | D41: 攻击 | E41: 轻击 | F41: =怪物总览!K13 -> 8 | G41: 1 | H41: =F41*G41 -> 8 | I41: 0 | J41: — | L41: =IF(OR(G41<1,I41<0),"\u203c","OK") -> OK
...
